Workbook

Sheet Resumo
A1: Bateria de formulações recalculadas
A2: Execução em memória com o motor atual, sem alterar as formulações persistidas. Ca:P preferencial: 2,0–2,5:1; faixa aceitável: 1,5–3,0:1.
A4: Formulações | D4: 100% concentrado | G4: Mistas | J4: Cenários com sucesso (contando mista fixa e otimizada)
A5: =COUNTA(Auditoria!A2:A74) -> 73 | D5: =COUNTIF(Auditoria!C2:C74,"CONCENTRADO") -> 54 | G5: =COUNTIF(Auditoria!C2:C74,"MISTA") -> 18 | J5: =COUNTIF('Dados Cenarios'!E2:E95,"SIM") -> 94
A8: Leitura do relatório: as três abas seguintes reproduzem o padrão da referência visual. MN (100 kg) é normalizada para fechar exatamente 100 kg de matéria natural, e MN (300 kg) é o triplo exato. Os casos inviáveis continuam listados com a causa.
A12: Cenário | B12: Execuções | C12: Sucessos | D12: Erros
A13: 100% concentrado | B13: =COUNTIF('Dados Cenarios'!D2:D95,"100% concentrado") -> 56 | C13: =COUNTIFS('Dados Cenarios'!D2:D95,"100% concentrado",'Dados Cenarios'!E2:E95,"SIM") -> 56 | D13: =B13-C13 -> 0
A14: Mistas 50% | B14: =COUNTIF('Dados Cenarios'!D2:D95,"Mista - 50% volumoso fixo") -> 19 | C14: =COUNTIFS('Dados Cenarios'!D2:D95,"Mista - 50% volumoso fixo",'Dados Cenarios'!E2:E95,"SIM") -> 19 | D14: =B14-C14 -> 0
A15: Mistas otimizadas | B15: =COUNTIF('Dados Cenarios'!D2:D95,"Mista - geração otimizada") -> 19 | C15: =COUNTIFS('Dados Cenarios'!D2:D95,"Mista - geração otimizada",'Dados Cenarios'!E2:E95,"SIM") -> 19 | D15: =B15-C15 -> 0
A18: Regras da execução
A19: 100% concentrado | B19: Alvo rígido de 0% de volumoso
A20: Mistas 50% | B20: Alvo rígido de 50% de volumoso
A21: Mistas otimizadas | B21: Busca automática do percentual estruturalmente viável
A22: Participações travadas | B22: Preservadas em todos os cenários
A23: Critério | B23: Objetivo EQUILIBRADO do motor atual
A26: Conteúdo das abas
A27: 100% Concentrado | B27: Blocos completos de todas as formulações exclusivamente concentradas.
A28: Mistas 50% | B28: Mesmas misturas recalculadas com 50% de volumoso fixo.
A29: Mistas Otimizadas | B29: Mesmas misturas sem alvo fixo de volumoso.
A30: Comparativo Mistas | B30: Diferenças de PB, NDT, FDN, Ca:P e número de desvios.
A31: Dados Cenarios | B31: Tabela plana de resultados para filtros e análise.
A32: Dados Ingredientes | B32: Participações, matéria natural, composição e contribuições auditáveis.
A33: Exigencias | B33: Operadores e limites nutricionais vigentes por formulação.
A34: Auditoria | B34: Metadados e causas de cenários não calculados.

Sheet 100% Concentrado
A1: Formulações 100% concentrado
A3: 11. Formulação ID 33: 1_id4
A4: Categoria: Cordeiros(as) 4 meses | Fase: Crescimento | PV: 20 kg | GMD: 0.2 kg/dia | CMS: 0.594 kg/dia | NRC ID: 1696 | Travas: 0
A5: Tipo | B5: Ingrediente | C5: % MS | D5: MS ing. (%) | E5: MN (100 kg) | F5: MN (300 kg) | G5: Origem
A6: Energético | B6: Trigo Farelo | C6: 9.12 | D6: 88.05 | E6: =IF(D6>0,(C6/D6)/SUMPRODUCT($C$6:$C$9/$D$6:$D$9)*100,"") -> 9.1316218 | F6: =IF(E6<>"",E6*3,"") -> 27.394865 | G6: Calculada
A7: Energético | B7: Milho Grão | C7: 66.26 | D7: 87.78 | E7: =IF(D7>0,(C7/D7)/SUMPRODUCT($C$6:$C$9/$D$6:$D$9)*100,"") -> 66.548503 | F7: =IF(E7<>"",E7*3,"") -> 199.64551 | G7: Calculada
A8: Proteico | B8: Soja Farelo | C8: 22.76 | D8: 88.48 | E8: =IF(D8>0,(C8/D8)/SUMPRODUCT($C$6:$C$9/$D$6:$D$9)*100,"") -> 22.678252 | F8: =IF(E8<>"",E8*3,"") -> 68.034757 | G8: Calculada
A9: Mineral | B9: Calcário calcítico | C9: 1.86 | D9: 99.89 | E9: =IF(D9>0,(C9/D9)/SUMPRODUCT($C$6:$C$9/$D$6:$D$9)*100,"") -> 1.6416228 | F9: =IF(E9<>"",E9*3,"") -> 4.9248683 | G9: Calculada
A10: TOTAL | C10: =SUM(C6:C9) -> 100 | E10: =SUM(E6:E9) -> 100 | F10: =SUM(F6:F9) -> 300
A11: PB (%) | B11: 18.68878 | C11: NDT (%) | D11: 81.884746 | E11: FDN (%) | F11: 17.042178
A12: Ca (%) | B12: 0.807024 | C12: P (%) | D12: 0.382208 | E12: Ca:P | F12: 2.1114786
A13: EE (%) | B13: 3.494464 | C13: Vol. (%) | D13: 0 | E13: Desvios | F13: 2
A14: Composição bromatológica: PB 18.69% | NDT 81.88% | FDN 17.04% | EE 3.49% | Ca 0.81% | P 0.38% | Ca:P 2.11:1 | Relação Ca:P: PREFERENCIAL
A15: Avaliação: FDN deficit (43.2%); P deficit (9.2%) | Motor: convergiu
A17: 12. Formulação ID 34: 2_id4
A18: Categoria: Cordeiros(as) 4 meses | Fase: Crescimento | PV: 20 kg | GMD: 0.2 kg/dia | CMS: 0.594 kg/dia | NRC ID: 1696 | Travas: 0
A19: Tipo | B19: Ingrediente | C19: % MS | D19: MS ing. (%) | E19: MN (100 kg) | F19: MN (300 kg) | G19: Origem
A20: Energético | B20: Milho Grão | C20: 40.27 | D20: 87.78 | E20: =IF(D20>0,(C20/D20)/SUMPRODUCT($C$20:$C$23/$D$20:$D$23)*100,"") -> 40.900429 | F20: =IF(E20<>"",E20*3,"") -> 122.70129 | G20: Calculada
A21: Energético | B21: Aveia Grão | C21: 38.47 | D21: 90.57 | E21: =IF(D21>0,(C21/D21)/SUMPRODUCT($C$20:$C$23/$D$20:$D$23)*100,"") -> 37.868633 | F21: =IF(E21<>"",E21*3,"") -> 113.6059 | G21: Calculada
A22: Proteico | B22: Soja Farelo | C22: 19.6 | D22: 88.48 | E22: =IF(D22>0,(C22/D22)/SUMPRODUCT($C$20:$C$23/$D$20:$D$23)*100,"") -> 19.749348 | F22: =IF(E22<>"",E22*3,"") -> 59.248045 | G22: Calculada
A23: Mineral | B23: Calcário calcítico | C23: 1.66 | D23: 99.89 | E23: =IF(D23>0,(C23/D23)/SUMPRODUCT($C$20:$C$23/$D$20:$D$23)*100,"") -> 1.4815895 | F23: =IF(E23<>"",E23*3,"") -> 4.4447684 | G23: Calculada
A24: TOTAL | C24: =SUM(C20:C23) -> 100 | E24: =SUM(E20:E23) -> 100 | F24: =SUM(F20:F23) -> 300
A25: PB (%) | B25: 18.688117 | C25: NDT (%) | D25: 79.412189 | E25: FDN (%) | F25: 19.459716
A26: Ca (%) | B26: 0.746782 | C26: P (%) | D26: 0.347206 | E26: Ca:P | F26: 2.1508326
A27: EE (%) | B27: 3.999797 | C27: Vol. (%) | D27: 0 | E27: Desvios | F27: 2
A28: Composição bromatológica: PB 18.69% | NDT 79.41% | FDN 19.46% | EE 4.00% | Ca 0.75% | P 0.35% | Ca:P 2.15:1 | Relação Ca:P: PREFERENCIAL
A29: Avaliação: FDN deficit (35.1%); P deficit (17.5%) | Motor: convergiu
A31: 13. Formulação ID 35: 6_id6
A32: Categoria: Cordeiros(as) 4 meses | Fase: Crescimento | PV: 20 kg | GMD: 0.3 kg/dia | CMS: 0.608 kg/dia | NRC ID: 1697 | Travas: 0
A33: Tipo | B33: Ingrediente | C33: % MS | D33: MS ing. (%) | E33: MN (100 kg) | F33: MN (300 kg) | G33: Origem
A34: Energético | B34: Trigo Farelo | C34: 20.13 | D34: 88.05 | E34: =IF(D34>0,(C34/D34)/SUMPRODUCT($C$34:$C$37/$D$34:$D$37)*100,"") -> 20.19301 | F34: =IF(E34<>"",E34*3,"") -> 60.57903 | G34: Calculada
A35: Energético | B35: Milho Grão | C35: 42.68 | D35: 87.78 | E35: =IF(D35>0,(C35/D35)/SUMPRODUCT($C$34:$C$37/$D$34:$D$37)*100,"") -> 42.945284 | F35: =IF(E35<>"",E35*3,"") -> 128.83585 | G35: Calculada
A36: Proteico | B36: Soja Farelo | C36: 34.88 | D36: 88.48 | E36: =IF(D36>0,(C36/D36)/SUMPRODUCT($C$34:$C$37/$D$34:$D$37)*100,"") -> 34.819137 | F36: =IF(E36<>"",E36*3,"") -> 104.45741 | G36: Calculada
A37: Mineral | B37: Calcário calcítico | C37: 2.31 | D37: 99.89 | E37: =IF(D37>0,(C37/D37)/SUMPRODUCT($C$34:$C$37/$D$34:$D$37)*100,"") -> 2.0425684 | F37: =IF(E37<>"",E37*3,"") -> 6.1277053 | G37: Calculada
A38: TOTAL | C38: =SUM(C34:C37) -> 100 | E38: =SUM(E34:E37) -> 100 | F38: =SUM(F34:F37) -> 300
A39: PB (%) | B39: 24.337624 | C39: NDT (%) | D39: 79.238983 | E39: FDN (%) | F39: 20.351856
A40: Ca (%) | B40: 1.02894 | C40: P (%) | D40: 0.496982 | E40: Ca:P | F40: 2.0703768
A41: EE (%) | B41: 3.115078 | C41: Vol. (%) | D41: 0 | E41: Desvios | F41: 2
A42: Composição bromatológica: PB 24.34% | NDT 79.24% | FDN 20.35% | EE 3.12% | Ca 1.03% | P 0.50% | Ca:P 2.07:1 | Relação Ca:P: PREFERENCIAL
A43: Avaliação: FDN deficit (32.2%); P deficit (13.7%) | Motor: convergiu
...

Sheet Mistas fixo
A1: Misturas volumoso/concentrado - fixo
A2: 6. Formulação ID 14: teste reuniao
A3: Categoria: Ovelhas | Fase: Início da lactação | PV: 20 kg | GMD: 0.2 kg/dia | CMS: 0.594 kg/dia | NRC ID: 1696 | Travas: 1
A4: Tipo | B4: Ingrediente | C4: % MS | D4: MS ing. (%) | E4: MN (100 kg) | F4: MN (300 kg) | G4: Origem
A5: Silagens | B5: Milho, Silagem | C5: 40 | D5: 31.59 | E5: =IF(D5>0,(C5/D5)/SUMPRODUCT($C$5:$C$10/$D$5:$D$10)*100,"") -> 56.811373 | F5: =IF(E5<>"",E5*3,"") -> 170.43412 | G5: Calculada
A6: Energético | B6: Milho Grão | C6: 31.924458 | D6: 87.78 | E6: =IF(D6>0,(C6/D6)/SUMPRODUCT($C$5:$C$10/$D$5:$D$10)*100,"") -> 16.317472 | F6: =IF(E6<>"",E6*3,"") -> 48.952416 | G6: Calculada
A7: Proteico | B7: Soja Farelo | C7: 16.297668 | D7: 88.48 | E7: =IF(D7>0,(C7/D7)/SUMPRODUCT($C$5:$C$10/$D$5:$D$10)*100,"") -> 8.2642849 | F7: =IF(E7<>"",E7*3,"") -> 24.792855 | G7: Calculada
A8: Proteico | B8: Uréia | C8: 1 | D8: 99 | E8: =IF(D8>0,(C8/D8)/SUMPRODUCT($C$5:$C$10/$D$5:$D$10)*100,"") -> 0.45319982 | F8: =IF(E8<>"",E8*3,"") -> 1.3595995 | G8: Calculada
A9: Mineral | B9: Calcário calcítico | C9: 0.77787411 | D9: 99.89 | E9: =IF(D9>0,(C9/D9)/SUMPRODUCT($C$5:$C$10/$D$5:$D$10)*100,"") -> 0.34939141 | F9: =IF(E9<>"",E9*3,"") -> 1.0481742 | G9: Calculada
A10: Forragens Verdes | B10: Alfafa | C10: 10 | D10: 25.2 | E10: =IF(D10>0,(C10/D10)/SUMPRODUCT($C$5:$C$10/$D$5:$D$10)*100,"") -> 17.804279 | F10: =IF(E10<>"",E10*3,"") -> 53.412836 | G10: Travada
A11: TOTAL | C11: =SUM(C5:C10) -> 100 | E11: =SUM(E5:E10) -> 100 | F11: =SUM(F5:F10) -> 300
A12: PB (%) | B12: 18.676869 | C12: NDT (%) | D12: 72.933718 | E12: FDN (%) | F12: 32.955881
A13: Ca (%) | B13: 0.62289562 | C13: P (%) | D13: 0.27578564 | E13: Ca:P | F13: 2.2586224
A14: EE (%) | B14: 3.2416515 | C14: Vol. (%) | D14: 50 | E14: Desvios | F14: 1
A15: Composição bromatológica: PB 18.68% | NDT 72.93% | FDN 32.96% | EE 3.24% | Ca 0.62% | P 0.28% | Ca:P 2.26:1 | Relação Ca:P: PREFERENCIAL
A16: Avaliação: P deficit (34.5%) | Motor: convergiu
A18: 7. Formulação ID 17: teste 2
A19: Categoria: Cordeiros(as) 4 meses | Fase: Crescimento | PV: 20 kg | GMD: 0.2 kg/dia | CMS: 0.594 kg/dia | NRC ID: 1696 | Travas: 3
A20: Tipo | B20: Ingrediente | C20: % MS | D20: MS ing. (%) | E20: MN (100 kg) | F20: MN (300 kg) | G20: Origem
A21: Silagens | B21: Milho, Silagem | C21: 50 | D21: 31.59 | E21: =IF(D21>0,(C21/D21)/SUMPRODUCT($C$21:$C$25/$D$21:$D$25)*100,"") -> 73.693218 | F21: =IF(E21<>"",E21*3,"") -> 221.07965 | G21: Calculada
A22: Energético | B22: Milho Grão | C22: 28.01 | D22: 87.78 | E22: =IF(D22>0,(C22/D22)/SUMPRODUCT($C$21:$C$25/$D$21:$D$25)*100,"") -> 14.856779 | F22: =IF(E22<>"",E22*3,"") -> 44.570338 | G22: Travada
A23: Proteico | B23: Soja Farelo | C23: 19.9 | D23: 88.48 | E23: =IF(D23>0,(C23/D23)/SUMPRODUCT($C$21:$C$25/$D$21:$D$25)*100,"") -> 10.47165 | F23: =IF(E23<>"",E23*3,"") -> 31.414949 | G23: Travada
A24: Proteico | B24: Uréia | C24: 1 | D24: 99 | E24: =IF(D24>0,(C24/D24)/SUMPRODUCT($C$21:$C$25/$D$21:$D$25)*100,"") -> 0.47029672 | F24: =IF(E24<>"",E24*3,"") -> 1.4108902 | G24: Calculada
A25: Mineral | B25: Calcário calcítico | C25: 1.09 | D25: 99.89 | E25: =IF(D25>0,(C25/D25)/SUMPRODUCT($C$21:$C$25/$D$21:$D$25)*100,"") -> 0.50805605 | F25: =IF(E25<>"",E25*3,"") -> 1.5241682 | G25: Travada
A26: TOTAL | C26: =SUM(C21:C25) -> 100 | E26: =SUM(E21:E25) -> 100 | F26: =SUM(F21:F25) -> 300
A27: PB (%) | B27: 18.68715 | C27: NDT (%) | D27: 71.727273 | E27: FDN (%) | F27: 34.724269
A28: Ca (%) | B28: 0.631188 | C28: P (%) | D28: 0.278564 | E28: Ca:P | F28: 2.2658635
A29: EE (%) | B29: 3.084068 | C29: Vol. (%) | D29: 50 | E29: Desvios | F29: 1
A30: Composição bromatológica: PB 18.69% | NDT 71.73% | FDN 34.72% | EE 3.08% | Ca 0.63% | P 0.28% | Ca:P 2.27:1 | Relação Ca:P: PREFERENCIAL
A31: Avaliação: P deficit (33.8%) | Motor: convergiu
A33: 10. Formulação ID 28: teste 5
A34: Categoria: Cordeiros(as) 4 meses | Fase: Crescimento | PV: 20 kg | GMD: 0.2 kg/dia | CMS: 0.594 kg/dia | NRC ID: 1696 | Travas: 0
A35: Tipo | B35: Ingrediente | C35: % MS | D35: MS ing. (%) | E35: MN (100 kg) | F35: MN (300 kg) | G35: Origem
A36: Silagens | B36: Milho, Silagem | C36: 50 | D36: 31.59 | E36: =IF(D36>0,(C36/D36)/SUMPRODUCT($C$36:$C$42/$D$36:$D$42)*100,"") -> 73.670986 | F36: =IF(E36<>"",E36*3,"") -> 221.01296 | G36: Calculada
A37: Energético | B37: Milho Grão | C37: 5.2645851 | D37: 87.78 | E37: =IF(D37>0,(C37/D37)/SUMPRODUCT($C$36:$C$42/$D$36:$D$42)*100,"") -> 2.7915453 | F37: =IF(E37<>"",E37*3,"") -> 8.3746359 | G37: Calculada
A38: Proteico | B38: Soja Farelo | C38: 20.036019 | D38: 88.48 | E38: =IF(D38>0,(C38/D38)/SUMPRODUCT($C$36:$C$42/$D$36:$D$42)*100,"") -> 10.540044 | F38: =IF(E38<>"",E38*3,"") -> 31.620133 | G38: Calculada
A39: Proteico | B39: DDGS30 | C39: 7.82095 | D39: 86 | E39: =IF(D39>0,(C39/D39)/SUMPRODUCT($C$36:$C$42/$D$36:$D$42)*100,"") -> 4.2328918 | F39: =IF(E39<>"",E39*3,"") -> 12.698675 | G39: Calculada
A40: Energético | B40: Trigo Farelo | C40: 14.292894 | D40: 88.05 | E40: =IF(D40>0,(C40/D40)/SUMPRODUCT($C$36:$C$42/$D$36:$D$42)*100,"") -> 7.5555645 | F40: =IF(E40<>"",E40*3,"") -> 22.666694 | G40: Calculada
A41: Mineral | B41: Calcário calcítico | C41: 1.5855516 | D41: 99.89 | E41: =IF(D41>0,(C41/D41)/SUMPRODUCT($C$36:$C$42/$D$36:$D$42)*100,"") -> 0.73881292 | F41: =IF(E41<>"",E41*3,"") -> 2.2164388 | G41: Calculada
A42: Mineral | B42: Sal Branco | C42: 1 | D42: 99 | E42: =IF(D42>0,(C42/D42)/SUMPRODUCT($C$36:$C$42/$D$36:$D$42)*100,"") -> 0.47015484 | F42: =IF(E42<>"",E42*3,"") -> 1.4104645 | G42: Calculada
...

Sheet Mistas Otimizadas
A1: Misturas volumoso/concentrado - geração otimizada
A3: 4. Formulação ID 11: teste reuniao
A4: Categoria: Ovelhas | Fase: Início da lactação | PV: 20 kg | GMD: 0.2 kg/dia | CMS: 0.594 kg/dia | NRC ID: 1696 | Travas: 0
A5: Tipo | B5: Ingrediente | C5: % MS | D5: MS ing. (%) | E5: MN (100 kg) | F5: MN (300 kg) | G5: Origem
A6: Energético | B6: Milho Grão | C6: 22.355159 | D6: 87.78 | E6: =IF(D6>0,(C6/D6)/SUMPRODUCT($C$6:$C$12/$D$6:$D$12)*100,"") -> 10.024913 | F6: =IF(E6<>"",E6*3,"") -> 30.074739 | G6: Calculada
A7: Proteico | B7: Soja Farelo | C7: 11.075023 | D7: 88.48 | E7: =IF(D7>0,(C7/D7)/SUMPRODUCT($C$6:$C$12/$D$6:$D$12)*100,"") -> 4.9271743 | F7: =IF(E7<>"",E7*3,"") -> 14.781523 | G7: Calculada
A8: Proteico | B8: Uréia | C8: 1 | D8: 99 | E8: =IF(D8>0,(C8/D8)/SUMPRODUCT($C$6:$C$12/$D$6:$D$12)*100,"") -> 0.39761543 | F8: =IF(E8<>"",E8*3,"") -> 1.1928463 | G8: Calculada
A9: Mineral | B9: Calcário calcítico | C9: 2.7286077 | D9: 99.89 | E9: =IF(D9>0,(C9/D9)/SUMPRODUCT($C$6:$C$12/$D$6:$D$12)*100,"") -> 1.0752699 | F9: =IF(E9<>"",E9*3,"") -> 3.2258098 | G9: Calculada
A10: Mineral | B10: Fosfato Monoamônio Defluorizado | C10: 0.1 | D10: 98.18 | E10: =IF(D10>0,(C10/D10)/SUMPRODUCT($C$6:$C$12/$D$6:$D$12)*100,"") -> 0.040093631 | F10: =IF(E10<>"",E10*3,"") -> 0.12028089 | G10: Calculada
A11: Forragens Verdes | B11: Azevém | C11: 40 | D11: 21.43 | E11: =IF(D11>0,(C11/D11)/SUMPRODUCT($C$6:$C$12/$D$6:$D$12)*100,"") -> 73.474433 | F11: =IF(E11<>"",E11*3,"") -> 220.4233 | G11: Calculada
A12: Energético | B12: Arroz Farelo Integral | C12: 22.741211 | D12: 88.98 | E12: =IF(D12>0,(C12/D12)/SUMPRODUCT($C$6:$C$12/$D$6:$D$12)*100,"") -> 10.060501 | F12: =IF(E12<>"",E12*3,"") -> 30.181503 | G12: Calculada
A13: TOTAL | C13: =SUM(C6:C12) -> 100 | E13: =SUM(E6:E12) -> 100 | F13: =SUM(F6:F12) -> 300
A14: PB (%) | B14: 18.676869 | C14: NDT (%) | D14: 73.016194 | E14: FDN (%) | F14: 33.578816
A15: Ca (%) | B15: 1.2844544 | C15: P (%) | D15: 0.64222721 | E15: Ca:P | F15: 2
A16: EE (%) | B16: 5.7744663 | C16: Vol. (%) | D16: 40 | E16: Desvios | F16: 0
A17: Composição bromatológica: PB 18.68% | NDT 73.02% | FDN 33.58% | EE 5.77% | Ca 1.28% | P 0.64% | Ca:P 2.00:1 | Relação Ca:P: ACEITAVEL
A18: Avaliação: Sem déficits ou excessos configurados. | Motor: convergiu
A20: 6. Formulação ID 14: teste reuniao
A21: Categoria: Ovelhas | Fase: Início da lactação | PV: 20 kg | GMD: 0.2 kg/dia | CMS: 0.594 kg/dia | NRC ID: 1696 | Travas: 1
A22: Tipo | B22: Ingrediente | C22: % MS | D22: MS ing. (%) | E22: MN (100 kg) | F22: MN (300 kg) | G22: Origem
A23: Silagens | B23: Milho, Silagem | C23: 42.25 | D23: 31.59 | E23: =IF(D23>0,(C23/D23)/SUMPRODUCT($C$23:$C$28/$D$23:$D$28)*100,"") -> 58.803737 | F23: =IF(E23<>"",E23*3,"") -> 176.41121 | G23: Calculada
A24: Energético | B24: Milho Grão | C24: 29.591638 | D24: 87.78 | E24: =IF(D24>0,(C24/D24)/SUMPRODUCT($C$23:$C$28/$D$23:$D$28)*100,"") -> 14.821811 | F24: =IF(E24<>"",E24*3,"") -> 44.465433 | G24: Calculada
A25: Proteico | B25: Soja Farelo | C25: 16.397569 | D25: 88.48 | E25: =IF(D25>0,(C25/D25)/SUMPRODUCT($C$23:$C$28/$D$23:$D$28)*100,"") -> 8.1482096 | F25: =IF(E25<>"",E25*3,"") -> 24.444629 | G25: Calculada
A26: Proteico | B26: Uréia | C26: 1 | D26: 99 | E26: =IF(D26>0,(C26/D26)/SUMPRODUCT($C$23:$C$28/$D$23:$D$28)*100,"") -> 0.44411214 | F26: =IF(E26<>"",E26*3,"") -> 1.3323364 | G26: Calculada
A27: Mineral | B27: Calcário calcítico | C27: 0.76079292 | D27: 99.89 | E27: =IF(D27>0,(C27/D27)/SUMPRODUCT($C$23:$C$28/$D$23:$D$28)*100,"") -> 0.33486695 | F27: =IF(E27<>"",E27*3,"") -> 1.0046009 | G27: Calculada
A28: Forragens Verdes | B28: Alfafa | C28: 10 | D28: 25.2 | E28: =IF(D28>0,(C28/D28)/SUMPRODUCT($C$23:$C$28/$D$23:$D$28)*100,"") -> 17.447263 | F28: =IF(E28<>"",E28*3,"") -> 52.341788 | G28: Travada
A29: TOTAL | C29: =SUM(C23:C28) -> 100 | E29: =SUM(E23:E28) -> 100 | F29: =SUM(F23:F28) -> 300
A30: PB (%) | B30: 18.676869 | C30: NDT (%) | D30: 72.427869 | E30: FDN (%) | F30: 33.879118
A31: Ca (%) | B31: 0.62289562 | C31: P (%) | D31: 0.27479632 | E31: Ca:P | F31: 2.2667539
A32: EE (%) | B32: 3.2163129 | C32: Vol. (%) | D32: 52.25 | E32: Desvios | F32: 1
A33: Composição bromatológica: PB 18.68% | NDT 72.43% | FDN 33.88% | EE 3.22% | Ca 0.62% | P 0.27% | Ca:P 2.27:1 | Relação Ca:P: PREFERENCIAL
A34: Avaliação: P deficit (34.7%) | Motor: convergiu
A36: 7. Formulação ID 17: teste 2
A37: Categoria: Cordeiros(as) 4 meses | Fase: Crescimento | PV: 20 kg | GMD: 0.2 kg/dia | CMS: 0.594 kg/dia | NRC ID: 1696 | Travas: 3
A38: Tipo | B38: Ingrediente | C38: % MS | D38: MS ing. (%) | E38: MN (100 kg) | F38: MN (300 kg) | G38: Origem
A39: Silagens | B39: Milho, Silagem | C39: 50.00377 | D39: 31.59 | E39: =IF(D39>0,(C39/D39)/SUMPRODUCT($C$39:$C$43/$D$39:$D$43)*100,"") -> 73.695986 | F39: =IF(E39<>"",E39*3,"") -> 221.08796 | G39: Calculada
A40: Energético | B40: Milho Grão | C40: 28.01 | D40: 87.78 | E40: =IF(D40>0,(C40/D40)/SUMPRODUCT($C$39:$C$43/$D$39:$D$43)*100,"") -> 14.856217 | F40: =IF(E40<>"",E40*3,"") -> 44.568652 | G40: Travada
A41: Proteico | B41: Soja Farelo | C41: 19.9 | D41: 88.48 | E41: =IF(D41>0,(C41/D41)/SUMPRODUCT($C$39:$C$43/$D$39:$D$43)*100,"") -> 10.471254 | F41: =IF(E41<>"",E41*3,"") -> 31.413761 | G41: Travada
A42: Proteico | B42: Uréia | C42: 0.99623022 | D42: 99 | E42: =IF(D42>0,(C42/D42)/SUMPRODUCT($C$39:$C$43/$D$39:$D$43)*100,"") -> 0.46850608 | F42: =IF(E42<>"",E42*3,"") -> 1.4055182 | G42: Calculada
A43: Mineral | B43: Calcário calcítico | C43: 1.09 | D43: 99.89 | E43: =IF(D43>0,(C43/D43)/SUMPRODUCT($C$39:$C$43/$D$39:$D$43)*100,"") -> 0.50803683 | F43: =IF(E43<>"",E43*3,"") -> 1.5241105 | G43: Travada
...

Sheet Comparativo Mistas
A1: ID | B1: Título | C1: Categoria | D1: Status 50% | E1: Status otimizada | F1: Vol. fixo | G1: Vol. otimizada | H1: Δ vol. | I1: PB fixo | J1: PB otimizada | K1: Δ PB | L1: NDT fixo | M1: NDT otimizada | N1: Δ NDT | O1: FDN fixo | P1: FDN otimizada | Q1: Δ FDN | R1: Ca:P fixo | S1: Ca:P otimizada | T1: Faixa Ca:P fixo | U1: Faixa Ca:P otimizada | V1: Desvios fixo | W1: Desvios otimizada | X1: Δ desvios | Y1: Resultado nutricional
A2: 14 | B2: teste reuniao | C2: Ovelhas | D2: OK | E2: OK | F2: 50 | G2: 52.25 | H2: =IF(OR(F2="",G2=""),"",G2-F2) -> 2.25 | I2: 18.676869 | J2: 18.676869 | K2: =IF(OR(I2="",J2=""),"",J2-I2) -> 0 | L2: 72.933718 | M2: 72.427869 | N2: =IF(OR(L2="",M2=""),"",M2-L2) -> -0.50584978 | O2: 32.955881 | P2: 33.879118 | Q2: =IF(OR(O2="",P2=""),"",P2-O2) -> 0.92323701 | R2: 2.2586224 | S2: 2.2667539 | T2: PREFERENCIAL | U2: PREFERENCIAL | V2: 1 | W2: 1 | X2: =IF(OR(V2="",W2=""),"",W2-V2) -> 0 | Y2: =IF(OR(D2<>"OK",E2<>"OK"),"Não comparável",IF(W2<V2,"Otimizada",IF(W2>V2,"50% fixo","Empate nutricional"))) -> Empate nutricional
A3: 17 | B3: teste 2 | C3: Cordeiros(as) 4 meses | D3: OK | E3: OK | F3: 50 | G3: 50.00377 | H3: =IF(OR(F3="",G3=""),"",G3-F3) -> 0.0037697771 | I3: 18.68715 | J3: 18.676869 | K3: =IF(OR(I3="",J3=""),"",J3-I3) -> -0.010281313 | L3: 71.727273 | M3: 71.729653 | N3: =IF(OR(L3="",M3=""),"",M3-L3) -> 0.0023798603 | O3: 34.724269 | P3: 34.726353 | Q3: =IF(OR(O3="",P3=""),"",P3-O3) -> 0.0020835558 | R3: 2.2658635 | S3: 2.2658458 | T3: PREFERENCIAL | U3: PREFERENCIAL | V3: 1 | W3: 1 | X3: =IF(OR(V3="",W3=""),"",W3-V3) -> 0 | Y3: =IF(OR(D3<>"OK",E3<>"OK"),"Não comparável",IF(W3<V3,"Otimizada",IF(W3>V3,"50% fixo","Empate nutricional"))) -> Empate nutricional
A4: 28 | B4: teste 5 | C4: Cordeiros(as) 4 meses | D4: OK | E4: OK | F4: 50 | G4: 27.225 | H4: =IF(OR(F4="",G4=""),"",G4-F4) -> -22.775 | I4: 18.676869 | J4: 18.676869 | K4: =IF(OR(I4="",J4=""),"",J4-I4) -> 0 | L4: 69.506036 | M4: 73.047988 | N4: =IF(OR(L4="",M4=""),"",M4-L4) -> 3.5419524 | O4: 40.390926 | P4: 33.871448 | Q4: =IF(OR(O4="",P4=""),"",P4-O4) -> -6.5194782 | R4: 2 | S4: 2 | T4: ACEITAVEL | U4: PREFERENCIAL | V4: 0 | W4: 0 | X4: =IF(OR(V4="",W4=""),"",W4-V4) -> 0 | Y4: =IF(OR(D4<>"OK",E4<>"OK"),"Não comparável",IF(W4<V4,"Otimizada",IF(W4>V4,"50% fixo","Empate nutricional"))) -> Empate nutricional
A5: 29 | B5: teste 6 | C5: Cordeiros(as) 4 meses | D5: OK | E5: OK | F5: 50 | G5: 22.275 | H5: =IF(OR(F5="",G5=""),"",G5-F5) -> -27.725 | I5: 12.234497 | J5: 12.246842 | K5: =IF(OR(I5="",J5=""),"",J5-I5) -> 0.012345557 | L5: 69.537484 | M5: 72.998562 | N5: =IF(OR(L5="",M5=""),"",M5-L5) -> 3.4610779 | O5: 41.06091 | P5: 33.775062 | Q5: =IF(OR(O5="",P5=""),"",P5-O5) -> -7.2858479 | R5: 2 | S5: 2.5 | T5: PREFERENCIAL | U5: PREFERENCIAL | V5: 0 | W5: 0 | X5: =IF(OR(V5="",W5=""),"",W5-V5) -> 0 | Y5: =IF(OR(D5<>"OK",E5<>"OK"),"Não comparável",IF(W5<V5,"Otimizada",IF(W5>V5,"50% fixo","Empate nutricional"))) -> Empate nutricional
A6: 30 | B6: teste 7 | C6: Cordeiros(as) 4 meses | D6: OK | E6: OK | F6: 50 | G6: 24.75 | H6: =IF(OR(F6="",G6=""),"",G6-F6) -> -25.25 | I6: 18.068176 | J6: 18.068176 | K6: =IF(OR(I6="",J6=""),"",J6-I6) -> 0 | L6: 69.699886 | M6: 73.380238 | N6: =IF(OR(L6="",M6=""),"",M6-L6) -> 3.6803524 | O6: 39.962842 | P6: 33.369631 | Q6: =IF(OR(O6="",P6=""),"",P6-O6) -> -6.5932104 | R6: 2 | S6: 2 | T6: ACEITAVEL | U6: PREFERENCIAL | V6: 0 | W6: 0 | X6: =IF(OR(V6="",W6=""),"",W6-V6) -> 0 | Y6: =IF(OR(D6<>"OK",E6<>"OK"),"Não comparável",IF(W6<V6,"Otimizada",IF(W6>V6,"50% fixo","Empate nutricional"))) -> Empate nutricional
A7: 32 | B7: teste 9 | C7: Cordeiros(as) 4 meses | D7: OK | E7: OK | F7: 50 | G7: 7.425 | H7: =IF(OR(F7="",G7=""),"",G7-F7) -> -42.575 | I7: 15.807872 | J7: 15.807872 | K7: =IF(OR(I7="",J7=""),"",J7-I7) -> 0 | L7: 65.957447 | M7: 66.392316 | N7: =IF(OR(L7="",M7=""),"",M7-L7) -> 0.43486952 | O7: 45.055845 | P7: 41.908035 | Q7: =IF(OR(O7="",P7=""),"",P7-O7) -> -3.1478094 | R7: 2.0039249 | S7: 2.5 | T7: PREFERENCIAL | U7: PREFERENCIAL | V7: 0 | W7: 0 | X7: =IF(OR(V7="",W7=""),"",W7-V7) -> 0 | Y7: =IF(OR(D7<>"OK",E7<>"OK"),"Não comparável",IF(W7<V7,"Otimizada",IF(W7>V7,"50% fixo","Empate nutricional"))) -> Empate nutricional
A8: 84 | B8: atz75 | C8: Cordeiros(as) 4 meses | D8: OK | E8: OK | F8: 50 | G8: 47.5 | H8: =IF(OR(F8="",G8=""),"",G8-F8) -> -2.5 | I8: 18.676869 | J8: 18.676869 | K8: =IF(OR(I8="",J8=""),"",J8-I8) -> 0 | L8: 71.747816 | M8: 72.309871 | N8: =IF(OR(L8="",M8=""),"",M8-L8) -> 0.56205532 | O8: 34.727127 | P8: 33.701308 | Q8: =IF(OR(O8="",P8=""),"",P8-O8) -> -1.0258189 | R8: 2.2364674 | S8: 2.2276752 | T8: PREFERENCIAL | U8: PREFERENCIAL | V8: 1 | W8: 1 | X8: =IF(OR(V8="",W8=""),"",W8-V8) -> 0 | Y8: =IF(OR(D8<>"OK",E8<>"OK"),"Não comparável",IF(W8<V8,"Otimizada",IF(W8>V8,"50% fixo","Empate nutricional"))) -> Empate nutricional
A9: 85 | B9: zoot25-1 | C9: Cordeiros(as) 4 meses | D9: OK | E9: OK | F9: 50 | G9: 47.5 | H9: =IF(OR(F9="",G9=""),"",G9-F9) -> -2.5 | I9: 18.676869 | J9: 18.676869 | K9: =IF(OR(I9="",J9=""),"",J9-I9) -> 0 | L9: 72.294613 | M9: 72.856668 | N9: =IF(OR(L9="",M9=""),"",M9-L9) -> 0.56205532 | O9: 34.945844 | P9: 33.920025 | Q9: =IF(OR(O9="",P9=""),"",P9-O9) -> -1.0258189 | R9: 2.0559778 | S9: 2.0485452 | T9: PREFERENCIAL | U9: PREFERENCIAL | V9: 1 | W9: 1 | X9: =IF(OR(V9="",W9=""),"",W9-V9) -> 0 | Y9: =IF(OR(D9<>"OK",E9<>"OK"),"Não comparável",IF(W9<V9,"Otimizada",IF(W9>V9,"50% fixo","Empate nutricional"))) -> Empate nutricional
A10: 86 | B10: aula dieta total | C10: Cordeiros(as) 4 meses | D10: OK | E10: OK | F10: 50 | G10: 47.5 | H10: =IF(OR(F10="",G10=""),"",G10-F10) -> -2.5 | I10: 18.68 | J10: 18.68 | K10: =IF(OR(I10="",J10=""),"",J10-I10) -> 0 | L10: 72.29425 | M10: 72.856305 | N10: =IF(OR(L10="",M10=""),"",M10-L10) -> 0.56205532 | O10: 34.94593 | P10: 33.920111 | Q10: =IF(OR(O10="",P10=""),"",P10-O10) -> -1.0258189 | R10: 2.0558057 | S10: 2.0483742 | T10: PREFERENCIAL | U10: PREFERENCIAL | V10: 1 | W10: 1 | X10: =IF(OR(V10="",W10=""),"",W10-V10) -> 0 | Y10: =IF(OR(D10<>"OK",E10<>"OK"),"Não comparável",IF(W10<V10,"Otimizada",IF(W10>V10,"50% fixo","Empate nutricional"))) -> Empate nutricional
A11: 87 | B11: atz1 | C11: Cordeiros(as) 4 meses | D11: OK | E11: OK | F11: 50 | G11: 47.025 | H11: =IF(OR(F11="",G11=""),"",G11-F11) -> -2.975 | I11: 18.68 | J11: 18.68 | K11: =IF(OR(I11="",J11=""),"",J11-I11) -> 0 | L11: 71.422695 | M11: 72.091541 | N11: =IF(OR(L11="",M11=""),"",M11-L11) -> 0.66884583 | O11: 34.804426 | P11: 33.583701 | Q11: =IF(OR(O11="",P11=""),"",P11-O11) -> -1.2207245 | R11: 2.0678447 | S11: 2.0589038 | T11: PREFERENCIAL | U11: PREFERENCIAL | V11: 1 | W11: 1 | X11: =IF(OR(V11="",W11=""),"",W11-V11) -> 0 | Y11: =IF(OR(D11<>"OK",E11<>"OK"),"Não comparável",IF(W11<V11,"Otimizada",IF(W11>V11,"50% fixo","Empate nutricional"))) -> Empate nutricional
A12: 88 | B12: ovino 2 24-42 | C12: Cordeiros(as) 4 meses | D12: OK | E12: OK | F12: 50 | G12: 44.55 | H12: =IF(OR(F12="",G12=""),"",G12-F12) -> -5.45 | I12: 12.406107 | J12: 12.406107 | K12: =IF(OR(I12="",J12=""),"",J12-I12) -> 0 | L12: 68.717197 | M12: 69.41189 | N12: =IF(OR(L12="",M12=""),"",M12-L12) -> 0.69469354 | O12: 40.572871 | P12: 39.154723 | Q12: =IF(OR(O12="",P12=""),"",P12-O12) -> -1.4181483 | R12: 2 | S12: 2 | T12: PREFERENCIAL | U12: ACEITAVEL | V12: 0 | W12: 0 | X12: =IF(OR(V12="",W12=""),"",W12-V12) -> 0 | Y12: =IF(OR(D12<>"OK",E12<>"OK"),"Não comparável",IF(W12<V12,"Otimizada",IF(W12>V12,"50% fixo","Empate nutricional"))) -> Empate nutricional
A13: 89 | B13: zoot38 | C13: Cordeiros(as) 4 meses | D13: OK | E13: OK | F13: 50 | G13: 47.5 | H13: =IF(OR(F13="",G13=""),"",G13-F13) -> -2.5 | I13: 18.676869 | J13: 18.676869 | K13: =IF(OR(I13="",J13=""),"",J13-I13) -> 0 | L13: 71.739518 | M13: 72.301426 | N13: =IF(OR(L13="",M13=""),"",M13-L13) -> 0.56190787 | O13: 34.72578 | P13: 33.699937 | Q13: =IF(OR(O13="",P13=""),"",P13-O13) -> -1.0258428 | R13: 2.2348652 | S13: 2.2260574 | T13: PREFERENCIAL | U13: PREFERENCIAL | V13: 1 | W13: 1 | X13: =IF(OR(V13="",W13=""),"",W13-V13) -> 0 | Y13: =IF(OR(D13<>"OK",E13<>"OK"),"Não comparável",IF(W13<V13,"Otimizada",IF(W13>V13,"50% fixo","Empate nutricional"))) -> Empate nutricional
... A17: 100 | B17: palestra | C17: Cordeiros(as) 4 meses | D17: OK | E17: OK | F17: 50 | G17: 47.5 | H17: =IF(OR(F17="",G17=""),"",G17-F17) -> -2.5 | I17: 18.68 | J17: 18.68 | K17: =IF(OR(I17="",J17=""),"",J17-I17) -> 0 | L17: 71.739155 | M17: 72.301063 | N17: =IF(OR(L17="",M17=""),"",M17-L17) -> 0.56190787 | O17: 34.725866 | P17: 33.700024 | Q17: =IF(OR(O17="",P17=""),"",P17-O17) -> -1.0258428 | R17: 2.2346619 | S17: 2.2258557 | T17: PREFERENCIAL | U17: PREFERENCIAL | V17: 1 | W17: 1 | X17: =IF(OR(V17="",W17=""),"",W17-V17) -> 0 | Y17: =IF(OR(D17<>"OK",E17<>"OK"),"Não comparável",IF(W17<V17,"Otimizada",IF(W17>V17,"50% fixo","Empate nutricional"))) -> Empate nutricional

Sheet Dados Cenarios
A1: Formulação ID | B1: Título | C1: Grupo | D1: Cenário | E1: Sucesso | F1: Categoria | G1: Fase | H1: PV (kg) | I1: GMD (kg/dia) | J1: CMS (kg/dia) | K1: Alvo volumoso (%) | L1: Volumoso aplicado (%) | M1: Concentrado aplicado (%) | N1: Soma MS (%) | O1: PB (%) | P1: NDT (%) | Q1: FDN (%) | R1: EE (%) | S1: Ca (%) | T1: P (%) | U1: Ca:P | V1: Status Ca:P | W1: Nº desvios | X1: Déficits/excessos | Y1: Motor convergiu | Z1: Origem do alvo | AA1: Erro
A2: 10 | B2: ovelhas leiteiras | C2: MISTA | D2: Mista - 50% volumoso fixo | E2: SIM | F2: Ovelhas | G2: Início da lactação | H2: 70 | I2: -0.031 | J2: 1.981 | K2: 50 | L2: 50 | M2: 50 | N2: 100 | O2: 14.74 | P2: 68.713476 | Q2: 33.225008 | R2: 2.1761611 | S2: 0.69661787 | T2: 0.34830893 | U2: 2 | V2: ACEITAVEL | W2: 0 | X2: Sem déficits ou excessos configurados. | Y2: SIM | Z2: heuristica_funcional
A3: 10 | B3: ovelhas leiteiras | C3: MISTA | D3: Mista - geração otimizada | E3: SIM | F3: Ovelhas | G3: Início da lactação | H3: 70 | I3: -0.031 | J3: 1.981 | L3: 47.5 | M3: 52.5 | N3: 100 | O3: 14.74 | P3: 69.172617 | Q3: 32.093935 | R3: 2.1241106 | S3: 0.69661787 | T3: 0.34830893 | U3: 2 | V3: PREFERENCIAL | W3: 0 | X3: Sem déficits ou excessos configurados. | Y3: SIM | Z3: otimizacao_percentual_hierarquica
A4: 11 | B4: teste reuniao | C4: MISTA | D4: Mista - 50% volumoso fixo | E4: SIM | F4: Ovelhas | G4: Início da lactação | H4: 20 | I4: 0.2 | J4: 0.594 | K4: 50 | L4: 50 | M4: 50 | N4: 100 | O4: 18.676869 | P4: 71.409632 | Q4: 37.531198 | R4: 5.1373747 | S4: 1.1567071 | T4: 0.57835353 | U4: 2 | V4: PREFERENCIAL | W4: 0 | X4: Sem déficits ou excessos configurados. | Y4: SIM | Z4: heuristica_funcional
A5: 11 | B5: teste reuniao | C5: MISTA | D5: Mista - geração otimizada | E5: SIM | F5: Ovelhas | G5: Início da lactação | H5: 20 | I5: 0.2 | J5: 0.594 | L5: 40 | M5: 60 | N5: 100 | O5: 18.676869 | P5: 73.016194 | Q5: 33.578816 | R5: 5.7744663 | S5: 1.2844544 | T5: 0.64222721 | U5: 2 | V5: ACEITAVEL | W5: 0 | X5: Sem déficits ou excessos configurados. | Y5: SIM | Z5: otimizacao_percentual_hierarquica
A6: 14 | B6: teste reuniao | C6: MISTA | D6: Mista - 50% volumoso fixo | E6: SIM | F6: Ovelhas | G6: Início da lactação | H6: 20 | I6: 0.2 | J6: 0.594 | K6: 50 | L6: 50 | M6: 50 | N6: 100 | O6: 18.676869 | P6: 72.933718 | Q6: 32.955881 | R6: 3.2416515 | S6: 0.62289562 | T6: 0.27578564 | U6: 2.2586224 | V6: PREFERENCIAL | W6: 1 | X6: P deficit (34.5%) | Y6: SIM | Z6: heuristica_funcional
A7: 14 | B7: teste reuniao | C7: MISTA | D7: Mista - geração otimizada | E7: SIM | F7: Ovelhas | G7: Início da lactação | H7: 20 | I7: 0.2 | J7: 0.594 | L7: 52.25 | M7: 47.75 | N7: 100 | O7: 18.676869 | P7: 72.427869 | Q7: 33.879118 | R7: 3.2163129 | S7: 0.62289562 | T7: 0.27479632 | U7: 2.2667539 | V7: PREFERENCIAL | W7: 1 | X7: P deficit (34.7%) | Y7: SIM | Z7: otimizacao_percentual_hierarquica
A8: 17 | B8: teste 2 | C8: MISTA | D8: Mista - 50% volumoso fixo | E8: SIM | F8: Cordeiros(as) 4 meses | G8: Crescimento | H8: 20 | I8: 0.2 | J8: 0.594 | K8: 50 | L8: 50 | M8: 50 | N8: 100 | O8: 18.68715 | P8: 71.727273 | Q8: 34.724269 | R8: 3.084068 | S8: 0.631188 | T8: 0.278564 | U8: 2.2658635 | V8: PREFERENCIAL | W8: 1 | X8: P deficit (33.8%) | Y8: SIM | Z8: heuristica_funcional
A9: 17 | B9: teste 2 | C9: MISTA | D9: Mista - geração otimizada | E9: SIM | F9: Cordeiros(as) 4 meses | G9: Crescimento | H9: 20 | I9: 0.2 | J9: 0.594 | L9: 50.00377 | M9: 49.99623 | N9: 100 | O9: 18.676869 | P9: 71.729653 | Q9: 34.726353 | R9: 3.084186 | S9: 0.63119931 | T9: 0.27857116 | U9: 2.2658458 | V9: PREFERENCIAL | W9: 1 | X9: P deficit (33.8%) | Y9: SIM | Z9: otimizacao_percentual_hierarquica
A10: 21 | B10: teste 5 | C10: MISTA | D10: Mista - 50% volumoso fixo | E10: SIM | F10: Cordeiros(as) 4 meses | G10: Crescimento | H10: 20 | I10: 0.1 | J10: 0.596 | K10: 50 | L10: 50 | M10: 50 | N10: 100 | O10: 27.75864 | P10: 71.04197 | Q10: 35.15093 | R10: 2.42075 | S10: 0.68487 | T10: 0.37383 | U10: 1.832036 | V10: ACEITAVEL | W10: 1 | X10: PB excesso (123.4%) | Y10: SIM | Z10: heuristica_funcional
A11: 21 | B11: teste 5 | C11: MISTA | D11: Mista - geração otimizada | E11: SIM | F11: Cordeiros(as) 4 meses | G11: Crescimento | H11: 20 | I11: 0.1 | J11: 0.596 | L11: 86.397427 | M11: 13.602573 | N11: 100 | O11: 12.426107 | P11: 64.716753 | Q11: 49.688874 | R11: 2.9247845 | S11: 0.67428077 | T11: 0.23608978 | U11: 2.8560355 | V11: ACEITAVEL | W11: 1 | X11: P deficit (6.2%) | Y11: SIM | Z11: otimizacao_percentual_hierarquica
A12: 28 | B12: teste 5 | C12: MISTA | D12: Mista - 50% volumoso fixo | E12: SIM | F12: Cordeiros(as) 4 meses | G12: Crescimento | H12: 20 | I12: 0.2 | J12: 0.594 | K12: 50 | L12: 50 | M12: 50 | N12: 100 | O12: 18.676869 | P12: 69.506036 | Q12: 40.390926 | R12: 2.8820041 | S12: 0.84175084 | T12: 0.42087542 | U12: 2 | V12: ACEITAVEL | W12: 0 | X12: Sem déficits ou excessos configurados. | Y12: SIM | Z12: heuristica_funcional
A13: 28 | B13: teste 5 | C13: MISTA | D13: Mista - geração otimizada | E13: SIM | F13: Cordeiros(as) 4 meses | G13: Crescimento | H13: 20 | I13: 0.2 | J13: 0.594 | L13: 27.225 | M13: 72.775 | N13: 100 | O13: 18.676869 | P13: 73.047988 | Q13: 33.871448 | R13: 3.1115923 | S13: 0.98480026 | T13: 0.49240013 | U13: 2 | V13: PREFERENCIAL | W13: 0 | X13: Sem déficits ou excessos configurados. | Y13: SIM | Z13: otimizacao_percentual_hierarquica
A14: 29 | B14: teste 6 | C14: MISTA | D14: Mista - 50% volumoso fixo | E14: SIM | F14: Cordeiros(as) 4 meses | G14: Crescimento | H14: 20 | I14: 0.15 | J14: 0.76 | K14: 50 | L14: 50 | M14: 50 | N14: 100 | O14: 12.234497 | P14: 69.537484 | Q14: 41.06091 | R14: 3.2714889 | S14: 0.77512256 | T14: 0.38756128 | U14: 2 | V14: PREFERENCIAL | W14: 0 | X14: Sem déficits ou excessos configurados. | Y14: SIM | Z14: heuristica_funcional
A15: 29 | B15: teste 6 | C15: MISTA | D15: Mista - geração otimizada | E15: SIM | F15: Cordeiros(as) 4 meses | G15: Crescimento | H15: 20 | I15: 0.15 | J15: 0.76 | L15: 22.275 | M15: 77.725 | N15: 100 | O15: 12.246842 | P15: 72.998562 | Q15: 33.775062 | R15: 3.5142686 | S15: 1.2239852 | T15: 0.48959408 | U15: 2.5 | V15: PREFERENCIAL | W15: 0 | X15: Sem déficits ou excessos configurados. | Y15: SIM | Z15: otimizacao_percentual_hierarquica
A16: 30 | B16: teste 7 | C16: MISTA | D16: Mista - 50% volumoso fixo | E16: SIM | F16: Cordeiros(as) 4 meses | G16: Crescimento | H16: 20 | I16: 0.2 | J16: 0.614 | K16: 50 | L16: 50 | M16: 50 | N16: 100 | O16: 18.068176 | P16: 69.699886 | Q16: 39.962842 | R16: 2.9222802 | S16: 0.81433225 | T16: 0.40716612 | U16: 2 | V16: ACEITAVEL | W16: 0 | X16: Sem déficits ou excessos configurados. | Y16: SIM | Z16: heuristica_funcional
A17: 30 | B17: teste 7 | C17: MISTA | D17: Mista - geração otimizada | E17: SIM | F17: Cordeiros(as) 4 meses | G17: Crescimento | H17: 20 | I17: 0.2 | J17: 0.614 | L17: 24.75 | M17: 75.25 | N17: 100 | O17: 18.068176 | P17: 73.380238 | Q17: 33.369631 | R17: 3.172328 | S17: 1.0002131 | T17: 0.50010657 | U17: 2 | V17: PREFERENCIAL | W17: 0 | X17: Sem déficits ou excessos configurados. | Y17: SIM | Z17: otimizacao_percentual_hierarquica
A18: 32 | B18: teste 9 | C18: MISTA | D18: Mista - 50% volumoso fixo | E18: SIM | F18: Cordeiros(as) 4 meses | G18: Crescimento | H18: 50 | I18: -0.034 | J18: 1.88 | K18: 50 | L18: 50 | M18: 50 | N18: 100 | O18: 15.807872 | P18: 65.957447 | Q18: 45.055845 | R18: 3.0383573 | S18: 0.9974646 | T18: 0.49775547 | U18: 2.0039249 | V18: PREFERENCIAL | W18: 0 | X18: Sem déficits ou excessos configurados. | Y18: SIM | Z18: heuristica_funcional
A19: 32 | B19: teste 9 | C19: MISTA | D19: Mista - geração otimizada | E19: SIM | F19: Cordeiros(as) 4 meses | G19: Crescimento | H19: 50 | I19: -0.034 | J19: 1.88 | L19: 7.425 | M19: 92.575 | N19: 100 | O19: 15.807872 | P19: 66.392316 | Q19: 41.908035 | R19: 3.3141834 | S19: 2.0826532 | T19: 0.8330613 | U19: 2.5 | V19: PREFERENCIAL | W19: 0 | X19: Sem déficits ou excessos configurados. | Y19: SIM | Z19: otimizacao_percentual_hierarquica
A20: 33 | B20: 1_id4 | C20: CONCENTRADO | D20: 100% concentrado | E20: SIM | F20: Cordeiros(as) 4 meses | G20: Crescimento | H20: 20 | I20: 0.2 | J20: 0.594 | K20: 0 | L20: 0 | M20: 100 | N20: 100 | O20: 18.68878 | P20: 81.884746 | Q20: 17.042178 | R20: 3.494464 | S20: 0.807024 | T20: 0.382208 | U20: 2.1114786 | V20: PREFERENCIAL | W20: 2 | X20: FDN deficit (43.2%); P deficit (9.2%) | Y20: SIM | Z20: referencia_validada_exata:LIVRO-001
A21: 34 | B21: 2_id4 | C21: CONCENTRADO | D21: 100% concentrado | E21: SIM | F21: Cordeiros(as) 4 meses | G21: Crescimento | H21: 20 | I21: 0.2 | J21: 0.594 | K21: 0 | L21: 0 | M21: 100 | N21: 100 | O21: 18.688117 | P21: 79.412189 | Q21: 19.459716 | R21: 3.999797 | S21: 0.746782 | T21: 0.347206 | U21: 2.1508326 | V21: PREFERENCIAL | W21: 2 | X21: FDN deficit (35.1%); P deficit (17.5%) | Y21: SIM | Z21: referencia_validada_exata:LIVRO-002
A22: 35 | B22: 6_id6 | C22: CONCENTRADO | D22: 100% concentrado | E22: SIM | F22: Cordeiros(as) 4 meses | G22: Crescimento | H22: 20 | I22: 0.3 | J22: 0.608 | K22: 0 | L22: 0 | M22: 100 | N22: 100 | O22: 24.337624 | P22: 79.238983 | Q22: 20.351856 | R22: 3.115078 | S22: 1.02894 | T22: 0.496982 | U22: 2.0703768 | V22: PREFERENCIAL | W22: 2 | X22: FDN deficit (32.2%); P deficit (13.7%) | Y22: SIM | Z22: referencia_validada_exata:LIVRO-006
A23: 36 | B23: 7_id6 | C23: CONCENTRADO | D23: 100% concentrado | E23: SIM | F23: Cordeiros(as) 4 meses | G23: Crescimento | H23: 20 | I23: 0.3 | J23: 0.608 | K23: 0 | L23: 0 | M23: 100 | N23: 100 | O23: 24.33935 | P23: 79.27418 | Q23: 18.181058 | R23: 3.501334 | S23: 0.962708 | T23: 0.38598 | U23: 2.4941914 | V23: PREFERENCIAL | W23: 2 | X23: FDN deficit (39.4%); P deficit (32.9%) | Y23: SIM | Z23: referencia_validada_exata:LIVRO-007
A24: 37 | B24: 10_id8 | C24: CONCENTRADO | D24: 100% concentrado | E24: SIM | F24: Cordeiros(as) 4 meses | G24: Crescimento | H24: 30 | I24: 0.2 | J24: 1.053 | K24: 0 | L24: 0 | M24: 100 | N24: 100 | O24: 12.444288 | P24: 81.209609 | Q24: 19.883011 | R24: 3.859767 | S24: 0.818586 | T24: 0.396788 | U24: 2.0630311 | V24: PREFERENCIAL | W24: 1 | X24: FDN deficit (33.7%) | Y24: SIM | Z24: referencia_validada_exata:LIVRO-010
A25: 38 | B25: 11_id8 | C25: CONCENTRADO | D25: 100% concentrado | E25: SIM | F25: Cordeiros(as) 4 meses | G25: Crescimento | H25: 30 | I25: 0.2 | J25: 1.053 | K25: 0 | L25: 0 | M25: 100 | N25: 100 | O25: 12.437577 | P25: 79.477868 | Q25: 20.602523 | R25: 4.514926 | S25: 0.619396 | T25: 0.302798 | U25: 2.0455749 | V25: PREFERENCIAL | W25: 1 | X25: FDN deficit (31.3%) | Y25: SIM | Z25: referencia_validada_exata:LIVRO-011
A26: 39 | B26: 15_id11 | C26: CONCENTRADO | D26: 100% concentrado | E26: SIM | F26: Cordeiros(as) 4 meses | G26: Crescimento | H26: 30 | I26: 0.25 | J26: 1.074 | K26: 0 | L26: 0 | M26: 100 | N26: 100 | O26: 14.024314 | P26: 79.746679 | Q26: 22.137939 | R26: 3.743268 | S26: 0.92788 | T26: 0.4578 | U26: 2.0268239 | V26: PREFERENCIAL | W26: 1 | X26: FDN deficit (26.2%) | Y26: SIM | Z26: referencia_validada_exata:LIVRO-015
A27: 43 | B27: 16_id11 | C27: CONCENTRADO | D27: 100% concentrado | E27: SIM | F27: Cordeiros(as) 4 meses | G27: Crescimento | H27: 30 | I27: 0.25 | J27: 1.074 | K27: 0 | L27: 0 | M27: 100 | N27: 100 | O27: 14.019731 | P27: 79.757526 | Q27: 19.796913 | R27: 4.331589 | S27: 0.687358 | T27: 0.31163 | U27: 2.2056862 | V27: PREFERENCIAL | W27: 1 | X27: FDN deficit (34.0%) | Y27: SIM | Z27: referencia_validada_exata:LIVRO-016
A28: 44 | B28: 1_id4 v2 | C28: CONCENTRADO | D28: 100% concentrado | E28: SIM | F28: Cordeiros(as) 4 meses | G28: Crescimento | H28: 20 | I28: 0.2 | J28: 0.594 | K28: 0 | L28: 0 | M28: 100 | N28: 100 | O28: 18.68878 | P28: 81.884746 | Q28: 17.042178 | R28: 3.494464 | S28: 0.807024 | T28: 0.382208 | U28: 2.1114786 | V28: PREFERENCIAL | W28: 2 | X28: FDN deficit (43.2%); P deficit (9.2%) | Y28: SIM | Z28: referencia_validada_exata:LIVRO-001
A29: 45 | B29: 2_id4 v2 | C29: CONCENTRADO | D29: 100% concentrado | E29: SIM | F29: Cordeiros(as) 4 meses | G29: Crescimento | H29: 20 | I29: 0.2 | J29: 0.594 | K29: 0 | L29: 0 | M29: 100 | N29: 100 | O29: 18.688117 | P29: 79.412189 | Q29: 19.459716 | R29: 3.999797 | S29: 0.746782 | T29: 0.347206 | U29: 2.1508326 | V29: PREFERENCIAL | W29: 2 | X29: FDN deficit (35.1%); P deficit (17.5%) | Y29: SIM | Z29: referencia_validada_exata:LIVRO-002
A30: 46 | B30: 6_id6 v2 | C30: CONCENTRADO | D30: 100% concentrado | E30: SIM | F30: Cordeiros(as) 4 meses | G30: Crescimento | H30: 20 | I30: 0.3 | J30: 0.608 | K30: 0 | L30: 0 | M30: 100 | N30: 100 | O30: 24.337624 | P30: 79.238983 | Q30: 20.351856 | R30: 3.115078 | S30: 1.02894 | T30: 0.496982 | U30: 2.0703768 | V30: PREFERENCIAL | W30: 2 | X30: FDN deficit (32.2%); P deficit (13.7%) | Y30: SIM | Z30: referencia_validada_exata:LIVRO-006
A31: 47 | B31: 7_id6 v2 | C31: CONCENTRADO | D31: 100% concentrado | E31: SIM | F31: Cordeiros(as) 4 meses | G31: Crescimento | H31: 20 | I31: 0.3 | J31: 0.626 | K31: 0 | L31: 0 | M31: 100 | N31: 100 | O31: 23.801917 | P31: 80.646849 | Q31: 16.944262 | R31: 3.4294263 | S31: 0.81469649 | T31: 0.37656703 | U31: 2.1634833 | V31: PREFERENCIAL | W31: 2 | X31: FDN deficit (43.5%); P deficit (32.6%) | Y31: SIM | Z31: heuristica_funcional
... A66: 84 | B66: atz75 | C66: MISTA | D66: Mista - 50% volumoso fixo | E66: SIM | F66: Cordeiros(as) 4 meses | G66: Crescimento | H66: 20 | I66: 0.2 | J66: 0.594 | K66: 50 | L66: 50 | M66: 50 | N66: 100 | O66: 18.676869 | P66: 71.747816 | Q66: 34.727127 | R66: 3.0857388 | S66: 0.62289562 | T66: 0.27851764 | U66: 2.2364674 | V66: PREFERENCIAL | W66: 1 | X66: P deficit (33.8%) | Y66: SIM | Z66: heuristica_funcional
A67: 84 | B67: atz75 | C67: MISTA | D67: Mista - geração otimizada | E67: SIM | F67: Cordeiros(as) 4 meses | G67: Crescimento | H67: 20 | I67: 0.2 | J67: 0.594 | L67: 47.5 | M67: 52.5 | N67: 100 | O67: 18.676869 | P67: 72.309871 | Q67: 33.701308 | R67: 3.1138928 | S67: 0.62289562 | T67: 0.27961689 | U67: 2.2276752 | V67: PREFERENCIAL | W67: 1 | X67: P deficit (33.6%) | Y67: SIM | Z67: otimizacao_percentual_hierarquica
A68: 85 | B68: zoot25-1 | C68: MISTA | D68: Mista - 50% volumoso fixo | E68: SIM | F68: Cordeiros(as) 4 meses | G68: Crescimento | H68: 20 | I68: 0.2 | J68: 0.594 | K68: 50 | L68: 50 | M68: 50 | N68: 100 | O68: 18.676869 | P68: 72.294613 | Q68: 34.945844 | R68: 2.9641907 | S68: 0.62289562 | T68: 0.30296807 | U68: 2.0559778 | V68: PREFERENCIAL | W68: 1 | X68: P deficit (28.0%) | Y68: SIM | Z68: heuristica_funcional
A69: 85 | B69: zoot25-1 | C69: MISTA | D69: Mista - geração otimizada | E69: SIM | F69: Cordeiros(as) 4 meses | G69: Crescimento | H69: 20 | I69: 0.2 | J69: 0.594 | L69: 47.5 | M69: 52.5 | N69: 100 | O69: 18.676869 | P69: 72.856668 | Q69: 33.920025 | R69: 2.9923447 | S69: 0.62289562 | T69: 0.30406731 | U69: 2.0485452 | V69: PREFERENCIAL | W69: 1 | X69: P deficit (27.8%) | Y69: SIM | Z69: otimizacao_percentual_hierarquica
A70: 86 | B70: aula dieta total | C70: MISTA | D70: Mista - 50% volumoso fixo | E70: SIM | F70: Cordeiros(as) 4 meses | G70: Crescimento | H70: 20 | I70: 0.2 | J70: 0.594 | K70: 50 | L70: 50 | M70: 50 | N70: 100 | O70: 18.68 | P70: 72.29425 | Q70: 34.94593 | R70: 2.9640019 | S70: 0.62289562 | T70: 0.30299344 | U70: 2.0558057 | V70: PREFERENCIAL | W70: 1 | X70: P deficit (28.0%) | Y70: SIM | Z70: heuristica_funcional
A71: 86 | B71: aula dieta total | C71: MISTA | D71: Mista - geração otimizada | E71: SIM | F71: Cordeiros(as) 4 meses | G71: Crescimento | H71: 20 | I71: 0.2 | J71: 0.594 | L71: 47.5 | M71: 52.5 | N71: 100 | O71: 18.68 | P71: 72.856305 | Q71: 33.920111 | R71: 2.9921559 | S71: 0.62289562 | T71: 0.30409268 | U71: 2.0483742 | V71: PREFERENCIAL | W71: 1 | X71: P deficit (27.7%) | Y71: SIM | Z71: otimizacao_percentual_hierarquica
A72: 87 | B72: atz1 | C72: MISTA | D72: Mista - 50% volumoso fixo | E72: SIM | F72: Cordeiros(as) 4 meses | G72: Crescimento | H72: 20 | I72: 0.2 | J72: 0.594 | K72: 50 | L72: 50 | M72: 50 | N72: 100 | O72: 18.68 | P72: 71.422695 | Q72: 34.804426 | R72: 2.9166755 | S72: 0.62289562 | T72: 0.30122941 | U72: 2.0678447 | V72: PREFERENCIAL | W72: 1 | X72: P deficit (28.4%) | Y72: SIM | Z72: heuristica_funcional
A73: 87 | B73: atz1 | C73: MISTA | D73: Mista - geração otimizada | E73: SIM | F73: Cordeiros(as) 4 meses | G73: Crescimento | H73: 20 | I73: 0.2 | J73: 0.594 | L73: 47.025 | M73: 52.975 | N73: 100 | O73: 18.68 | P73: 72.091541 | Q73: 33.583701 | R73: 2.9501787 | S73: 0.62289562 | T73: 0.30253751 | U73: 2.0589038 | V73: PREFERENCIAL | W73: 1 | X73: P deficit (28.1%) | Y73: SIM | Z73: otimizacao_percentual_hierarquica
A74: 88 | B74: ovino 2 24-42 | C74: MISTA | D74: Mista - 50% volumoso fixo | E74: SIM | F74: Cordeiros(as) 4 meses | G74: Crescimento | H74: 20 | I74: 0.1 | J74: 0.596 | K74: 50 | L74: 50 | M74: 50 | N74: 100 | O74: 12.406107 | P74: 68.717197 | Q74: 40.572871 | R74: 3.4484053 | S74: 0.69552208 | T74: 0.34776104 | U74: 2 | V74: PREFERENCIAL | W74: 0 | X74: Sem déficits ou excessos configurados. | Y74: SIM | Z74: heuristica_funcional
...

Sheet Dados Ingredientes
A1: Formulação ID | B1: Cenário | C1: Ingrediente ID | D1: Tipo | E1: Ingrediente | F1: Classificação | G1: Origem participação | H1: % MS persistida | I1: % MS recalculada | J1: MS ingrediente (%) | K1: MN (100 kg) | L1: MN (300 kg) | M1: PB ing. (%) | N1: NDT ing. (%) | O1: FDN ing. (%) | P1: EE ing. (%) | Q1: Ca ing. (%) | R1: P ing. (%) | S1: Contrib. PB | T1: Contrib. NDT | U1: Contrib. FDN | V1: Contrib. EE | W1: Contrib. Ca | X1: Contrib. P
A2: 7 | B2: Mista - geração otimizada | C2: 185 | D2: Energético | E2: Milho Gão Silagem | F2: Concentrado | G2: CALCULADA | H2: 10 | I2: 0 | J2: 71.82 | K2: =IF(J2>0,(I2/J2)/SUMPRODUCT($I$2:$I$7/$J$2:$J$7)*100,"") -> 0 | L2: =IF(K2<>"",K2*3,"") -> 0 | M2: 9.84 | N2: 84.09 | O2: 11.73 | P2: 5.31 | Q2: 0.03 | R2: 0.25 | S2: =I2/100*M2 -> 0 | T2: =I2/100*N2 -> 0 | U2: =I2/100*O2 -> 0 | V2: =I2/100*P2 -> 0 | W2: =I2/100*Q2 -> 0 | X2: =I2/100*R2 -> 0
A3: 7 | B3: Mista - geração otimizada | C3: 172 | D3: Energético | E3: Arroz Farelo Integral | F3: Concentrado | G3: CALCULADA | H3: 0 | I3: 7.3665356 | J3: 88.98 | K3: =IF(J3>0,(I3/J3)/SUMPRODUCT($I$2:$I$7/$J$2:$J$7)*100,"") -> 7.2976159 | L3: =IF(K3<>"",K3*3,"") -> 21.892848 | M3: 13.73 | N3: 83.51 | O3: 24.43 | P3: 15.84 | Q3: 0.11 | R3: 1.72 | S3: =I3/100*M3 -> 1.0114253 | T3: =I3/100*N3 -> 6.1517939 | U3: =I3/100*O3 -> 1.7996447 | V3: =I3/100*P3 -> 1.1668592 | W3: =I3/100*Q3 -> 0.0081031892 | X3: =I3/100*R3 -> 0.12670441
A4: 7 | B4: Mista - geração otimizada | C4: 213 | D4: Mineral | E4: Calcário calcítico | F4: Concentrado | G4: CALCULADA | H4: 0 | I4: 0.043549621 | J4: 99.89 | K4: =IF(J4>0,(I4/J4)/SUMPRODUCT($I$2:$I$7/$J$2:$J$7)*100,"") -> 0.038430185 | L4: =IF(K4<>"",K4*3,"") -> 0.11529055 | M4: 0 | N4: 0 | O4: 0 | P4: 0 | Q4: 37.35 | R4: 0.01 | S4: =I4/100*M4 -> 0 | T4: =I4/100*N4 -> 0 | U4: =I4/100*O4 -> 0 | V4: =I4/100*P4 -> 0 | W4: =I4/100*Q4 -> 0.016265783 | X4: =I4/100*R4 -> 4.3549621e-06
A5: 7 | B5: Mista - geração otimizada | C5: 121 | D5: Forragens Secas | E5: Capim Tanzânia Feno | F5: Volumoso | G5: MANUAL_TRAVADA | H5: 50 | I5: 50 | J5: 86.81 | K5: =IF(J5>0,(I5/J5)/SUMPRODUCT($I$2:$I$7/$J$2:$J$7)*100,"") -> 50.770374 | L5: =IF(K5<>"",K5*3,"") -> 152.31112 | M5: 7.65 | N5: 34.54 | O5: 70.04 | P5: 1.59 | Q5: 0.6 | R5: 0.04 | S5: =I5/100*M5 -> 3.825 | T5: =I5/100*N5 -> 17.27 | U5: =I5/100*O5 -> 35.02 | V5: =I5/100*P5 -> 0.795 | W5: =I5/100*Q5 -> 0.3 | X5: =I5/100*R5 -> 0.02
A6: 7 | B6: Mista - geração otimizada | C6: 117 | D6: Forragens Secas | E6: Capim Bráquiaria Brazintha Feno | F6: Volumoso | G6: MANUAL_TRAVADA | H6: 40 | I6: 40 | J6: 89.65 | K6: =IF(J6>0,(I6/J6)/SUMPRODUCT($I$2:$I$7/$J$2:$J$7)*100,"") -> 39.329625 | L6: =IF(K6<>"",K6*3,"") -> 117.98888 | M6: 4.09 | N6: 40.3 | O6: 78.46 | P6: 0.92 | Q6: 0.39 | R6: 0.1 | S6: =I6/100*M6 -> 1.636 | T6: =I6/100*N6 -> 16.12 | U6: =I6/100*O6 -> 31.384 | V6: =I6/100*P6 -> 0.368 | W6: =I6/100*Q6 -> 0.156 | X6: =I6/100*R6 -> 0.04
A7: 7 | B7: Mista - geração otimizada | C7: 183 | D7: Energético | E7: Milheto Grão | F7: Concentrado | G7: CALCULADA | H7: 0 | I7: 2.5899147 | J7: 89.04 | K7: =IF(J7>0,(I7/J7)/SUMPRODUCT($I$2:$I$7/$J$2:$J$7)*100,"") -> 2.5639552 | L7: =IF(K7<>"",K7*3,"") -> 7.6918655 | M7: 15.43 | N7: 77.42 | O7: 21.48 | P7: 4.75 | Q7: 0.05 | R7: 0.23 | S7: =I7/100*M7 -> 0.39962384 | T7: =I7/100*N7 -> 2.005112 | U7: =I7/100*O7 -> 0.55631368 | V7: =I7/100*P7 -> 0.12302095 | W7: =I7/100*Q7 -> 0.0012949574 | X7: =I7/100*R7 -> 0.0059568039
A8: 8 | B8: 100% concentrado | C8: 182 | D8: Energético | E8: Mihho Desintegrado Com Palha e Sabugo | F8: Concentrado | G8: CALCULADA | H8: 91.442921 | I8: 15.277334 | J8: 87.9 | K8: =IF(J8>0,(I8/J8)/SUMPRODUCT($I$8:$I$11/$J$8:$J$11)*100,"") -> 15.285687 | L8: =IF(K8<>"",K8*3,"") -> 45.857062 | M8: 8.07 | N8: 63.71 | O8: 38.2 | P8: 2.99 | Q8: 0.05 | R8: 0.22 | S8: =I8/100*M8 -> 1.2328809 | T8: =I8/100*N8 -> 9.7331898 | U8: =I8/100*O8 -> 5.8359418 | V8: =I8/100*P8 -> 0.4567923 | W8: =I8/100*Q8 -> 0.0076386672 | X8: =I8/100*R8 -> 0.033610136
A9: 8 | B9: 100% concentrado | C9: 188 | D9: Energético | E9: Milho Grão | F9: Concentrado | G9: CALCULADA | H9: 4.1074862 | I9: 81.340492 | J9: 87.78 | K9: =IF(J9>0,(I9/J9)/SUMPRODUCT($I$8:$I$11/$J$8:$J$11)*100,"") -> 81.496223 | L9: =IF(K9<>"",K9*3,"") -> 244.48867 | M9: 9.1 | N9: 86.03 | O9: 14.39 | P9: 4.18 | Q9: 0.03 | R9: 0.25 | S9: =I9/100*M9 -> 7.4019847 | T9: =I9/100*N9 -> 69.977225 | U9: =I9/100*O9 -> 11.704897 | V9: =I9/100*P9 -> 3.4000326 | W9: =I9/100*Q9 -> 0.024402148 | X9: =I9/100*R9 -> 0.20335123
A10: 8 | B10: 100% concentrado | C10: 213 | D10: Mineral | E10: Calcário calcítico | F10: Concentrado | G10: CALCULADA | H10: 0.525389 | I10: 1.266093 | J10: 99.89 | K10: =IF(J10>0,(I10/J10)/SUMPRODUCT($I$8:$I$11/$J$8:$J$11)*100,"") -> 1.1147304 | L10: =IF(K10<>"",K10*3,"") -> 3.3441912 | M10: 0 | N10: 0 | O10: 0 | P10: 0 | Q10: 37.35 | R10: 0.01 | S10: =I10/100*M10 -> 0 | T10: =I10/100*N10 -> 0 | U10: =I10/100*O10 -> 0 | V10: =I10/100*P10 -> 0 | W10: =I10/100*Q10 -> 0.47288573 | X10: =I10/100*R10 -> 0.0001266093
A11: 8 | B11: 100% concentrado | C11: 208 | D11: Proteico | E11: Soja Farelo | F11: Concentrado | G11: CALCULADA | H11: 3.9242036 | I11: 2.1160809 | J11: 88.48 | K11: =IF(J11>0,(I11/J11)/SUMPRODUCT($I$8:$I$11/$J$8:$J$11)*100,"") -> 2.103359 | L11: =IF(K11<>"",K11*3,"") -> 6.3100771 | M11: 48.76 | N11: 80.73 | O11: 15.37 | P11: 1.75 | Q11: 0.33 | R11: 0.57 | S11: =I11/100*M11 -> 1.031801 | T11: =I11/100*N11 -> 1.7083121 | U11: =I11/100*O11 -> 0.32524163 | V11: =I11/100*P11 -> 0.037031415 | W11: =I11/100*Q11 -> 0.0069830669 | X11: =I11/100*R11 -> 0.012061661
A12: 10 | B12: Mista - 50% volumoso fixo | C12: 168 | D12: Silagens | E12: Milho, Silagem | F12: Volumoso | G12: CALCULADA | H12: 47.474949 | I12: 50 | J12: 31.59 | K12: =IF(J12>0,(I12/J12)/SUMPRODUCT($I$12:$I$16/$J$12:$J$16)*100,"") -> 74.004558 | L12: =IF(K12<>"",K12*3,"") -> 222.01368 | M12: 7.27 | N12: 63.13 | O12: 55.27 | P12: 3.13 | Q12: 0.3 | R12: 0.19 | S12: =I12/100*M12 -> 3.635 | T12: =I12/100*N12 -> 31.565 | U12: =I12/100*O12 -> 27.635 | V12: =I12/100*P12 -> 1.565 | W12: =I12/100*Q12 -> 0.15 | X12: =I12/100*R12 -> 0.095
A13: 10 | B13: Mista - 50% volumoso fixo | C13: 178 | D13: Energético | E13: Mandioca Farinha | F13: Concentrado | G13: CALCULADA | H13: 23.835862 | I13: 22.797269 | J13: 90.77 | K13: =IF(J13>0,(I13/J13)/SUMPRODUCT($I$12:$I$16/$J$12:$J$16)*100,"") -> 11.742987 | L13: =IF(K13<>"",K13*3,"") -> 35.228961 | M13: 1.6 | N13: 84.95 | O13: 9.67 | P13: 0.99 | Q13: 0.18 | R13: 0.03 | S13: =I13/100*M13 -> 0.36475631 | T13: =I13/100*N13 -> 19.36628 | U13: =I13/100*O13 -> 2.2044959 | V13: =I13/100*P13 -> 0.22569297 | W13: =I13/100*Q13 -> 0.041035085 | X13: =I13/100*R13 -> 0.0068391808
A14: 10 | B14: Mista - 50% volumoso fixo | C14: 208 | D14: Proteico | E14: Soja Farelo | F14: Concentrado | G14: CALCULADA | H14: 24.667303 | I14: 22.026751 | J14: 88.48 | K14: =IF(J14>0,(I14/J14)/SUMPRODUCT($I$12:$I$16/$J$12:$J$16)*100,"") -> 11.639744 | L14: =IF(K14<>"",K14*3,"") -> 34.919231 | M14: 48.76 | N14: 80.73 | O14: 15.37 | P14: 1.75 | Q14: 0.33 | R14: 0.57 | S14: =I14/100*M14 -> 10.740244 | T14: =I14/100*N14 -> 17.782196 | U14: =I14/100*O14 -> 3.3855116 | V14: =I14/100*P14 -> 0.38546814 | W14: =I14/100*Q14 -> 0.072688278 | X14: =I14/100*R14 -> 0.12555248
A15: 10 | B15: Mista - 50% volumoso fixo | C15: 213 | D15: Mineral | E15: Calcário calcítico | F15: Concentrado | G15: CALCULADA | H15: 0.31986647 | I15: 1.1221188 | J15: 99.89 | K15: =IF(J15>0,(I15/J15)/SUMPRODUCT($I$12:$I$16/$J$12:$J$16)*100,"") -> 0.52523653 | L15: =IF(K15<>"",K15*3,"") -> 1.5757096 | M15: 0 | N15: 0 | O15: 0 | P15: 0 | Q15: 37.35 | R15: 0.01 | S15: =I15/100*M15 -> 0 | T15: =I15/100*N15 -> 0 | U15: =I15/100*O15 -> 0 | V15: =I15/100*P15 -> 0 | W15: =I15/100*Q15 -> 0.41911138 | X15: =I15/100*R15 -> 0.00011221188
A16: 10 | B16: Mista - 50% volumoso fixo | C16: 214 | D16: Mineral | E16: Cromo Orgânico | F16: Concentrado | G16: CALCULADA | H16: 3.7020187 | I16: 4.0538612 | J16: 90.8 | K16: =IF(J16>0,(I16/J16)/SUMPRODUCT($I$12:$I$16/$J$12:$J$16)*100,"") -> 2.0874742 | L16: =IF(K16<>"",K16*3,"") -> 6.2624226 | M16: 0 | N16: 0 | O16: 0 | P16: 0 | Q16: 0.34 | R16: 2.98 | S16: =I16/100*M16 -> 0 | T16: =I16/100*N16 -> 0 | U16: =I16/100*O16 -> 0 | V16: =I16/100*P16 -> 0 | W16: =I16/100*Q16 -> 0.013783128 | X16: =I16/100*R16 -> 0.12080506
A17: 10 | B17: Mista - geração otimizada | C17: 168 | D17: Silagens | E17: Milho, Silagem | F17: Volumoso | G17: CALCULADA | H17: 47.474949 | I17: 47.5 | J17: 31.59 | K17: =IF(J17>0,(I17/J17)/SUMPRODUCT($I$17:$I$21/$J$17:$J$21)*100,"") -> 72.039576 | L17: =IF(K17<>"",K17*3,"") -> 216.11873 | M17: 7.27 | N17: 63.13 | O17: 55.27 | P17: 3.13 | Q17: 0.3 | R17: 0.19 | S17: =I17/100*M17 -> 3.45325 | T17: =I17/100*N17 -> 29.98675 | U17: =I17/100*O17 -> 26.25325 | V17: =I17/100*P17 -> 1.48675 | W17: =I17/100*Q17 -> 0.1425 | X17: =I17/100*R17 -> 0.09025
A18: 10 | B18: Mista - geração otimizada | C18: 178 | D18: Energético | E18: Mandioca Farinha | F18: Concentrado | G18: CALCULADA | H18: 23.835862 | I18: 24.907178 | J18: 90.77 | K18: =IF(J18>0,(I18/J18)/SUMPRODUCT($I$17:$I$21/$J$17:$J$21)*100,"") -> 13.146476 | L18: =IF(K18<>"",K18*3,"") -> 39.439428 | M18: 1.6 | N18: 84.95 | O18: 9.67 | P18: 0.99 | Q18: 0.18 | R18: 0.03 | S18: =I18/100*M18 -> 0.39851485 | T18: =I18/100*N18 -> 21.158648 | U18: =I18/100*O18 -> 2.4085241 | V18: =I18/100*P18 -> 0.24658106 | W18: =I18/100*Q18 -> 0.044832921 | X18: =I18/100*R18 -> 0.0074721535
A19: 10 | B19: Mista - geração otimizada | C19: 208 | D19: Proteico | E19: Soja Farelo | F19: Concentrado | G19: CALCULADA | H19: 24.667303 | I19: 22.330261 | J19: 88.48 | K19: =IF(J19>0,(I19/J19)/SUMPRODUCT($I$17:$I$21/$J$17:$J$21)*100,"") -> 12.091379 | L19: =IF(K19<>"",K19*3,"") -> 36.274138 | M19: 48.76 | N19: 80.73 | O19: 15.37 | P19: 1.75 | Q19: 0.33 | R19: 0.57 | S19: =I19/100*M19 -> 10.888235 | T19: =I19/100*N19 -> 18.02722 | U19: =I19/100*O19 -> 3.4321611 | V19: =I19/100*P19 -> 0.39077956 | W19: =I19/100*Q19 -> 0.073689861 | X19: =I19/100*R19 -> 0.12728249
A20: 10 | B20: Mista - geração otimizada | C20: 213 | D20: Mineral | E20: Calcário calcítico | F20: Concentrado | G20: CALCULADA | H20: 0.31986647 | I20: 1.1286203 | J20: 99.89 | K20: =IF(J20>0,(I20/J20)/SUMPRODUCT($I$17:$I$21/$J$17:$J$21)*100,"") -> 0.54131868 | L20: =IF(K20<>"",K20*3,"") -> 1.623956 | M20: 0 | N20: 0 | O20: 0 | P20: 0 | Q20: 37.35 | R20: 0.01 | S20: =I20/100*M20 -> 0 | T20: =I20/100*N20 -> 0 | U20: =I20/100*O20 -> 0 | V20: =I20/100*P20 -> 0 | W20: =I20/100*Q20 -> 0.42153969 | X20: =I20/100*R20 -> 0.00011286203
A21: 10 | B21: Mista - geração otimizada | C21: 214 | D21: Mineral | E21: Cromo Orgânico | F21: Concentrado | G21: CALCULADA | H21: 3.7020187 | I21: 4.1339407 | J21: 90.8 | K21: =IF(J21>0,(I21/J21)/SUMPRODUCT($I$17:$I$21/$J$17:$J$21)*100,"") -> 2.1812506 | L21: =IF(K21<>"",K21*3,"") -> 6.5437517 | M21: 0 | N21: 0 | O21: 0 | P21: 0 | Q21: 0.34 | R21: 2.98 | S21: =I21/100*M21 -> 0 | T21: =I21/100*N21 -> 0 | U21: =I21/100*O21 -> 0 | V21: =I21/100*P21 -> 0 | W21: =I21/100*Q21 -> 0.014055398 | X21: =I21/100*R21 -> 0.12319143
A22: 11 | B22: Mista - 50% volumoso fixo | C22: 188 | D22: Energético | E22: Milho Grão | F22: Concentrado | G22: CALCULADA | H22: 28.01 | I22: 17.867161 | J22: 87.78 | K22: =IF(J22>0,(I22/J22)/SUMPRODUCT($I$22:$I$28/$J$22:$J$28)*100,"") -> 7.0321942 | L22: =IF(K22<>"",K22*3,"") -> 21.096583 | M22: 9.1 | N22: 86.03 | O22: 14.39 | P22: 4.18 | Q22: 0.03 | R22: 0.25 | S22: =I22/100*M22 -> 1.6259117 | T22: =I22/100*N22 -> 15.371119 | U22: =I22/100*O22 -> 2.5710845 | V22: =I22/100*P22 -> 0.74684735 | W22: =I22/100*Q22 -> 0.0053601484 | X22: =I22/100*R22 -> 0.044667903
A23: 11 | B23: Mista - 50% volumoso fixo | C23: 208 | D23: Proteico | E23: Soja Farelo | F23: Concentrado | G23: CALCULADA | H23: 19.9 | I23: 10.427856 | J23: 88.48 | K23: =IF(J23>0,(I23/J23)/SUMPRODUCT($I$22:$I$28/$J$22:$J$28)*100,"") -> 4.071747 | L23: =IF(K23<>"",K23*3,"") -> 12.215241 | M23: 48.76 | N23: 80.73 | O23: 15.37 | P23: 1.75 | Q23: 0.33 | R23: 0.57 | S23: =I23/100*M23 -> 5.0846226 | T23: =I23/100*N23 -> 8.4184081 | U23: =I23/100*O23 -> 1.6027615 | V23: =I23/100*P23 -> 0.18248748 | W23: =I23/100*Q23 -> 0.034411925 | X23: =I23/100*R23 -> 0.059438779
A24: 11 | B24: Mista - 50% volumoso fixo | C24: 211 | D24: Proteico | E24: Uréia | F24: Concentrado | G24: CALCULADA | H24: 1 | I24: 1 | J24: 99 | K24: =IF(J24>0,(I24/J24)/SUMPRODUCT($I$22:$I$28/$J$22:$J$28)*100,"") -> 0.34897609 | L24: =IF(K24<>"",K24*3,"") -> 1.0469283 | M24: 280 | N24: 0 | O24: 0 | P24: 0 | Q24: 0 | R24: 0 | S24: =I24/100*M24 -> 2.8 | T24: =I24/100*N24 -> 0 | U24: =I24/100*O24 -> 0 | V24: =I24/100*P24 -> 0 | W24: =I24/100*Q24 -> 0 | X24: =I24/100*R24 -> 0
A25: 11 | B25: Mista - 50% volumoso fixo | C25: 213 | D25: Mineral | E25: Calcário calcítico | F25: Concentrado | G25: CALCULADA | H25: 1.09 | I25: 2.2777108 | J25: 99.89 | K25: =IF(J25>0,(I25/J25)/SUMPRODUCT($I$22:$I$28/$J$22:$J$28)*100,"") -> 0.78778451 | L25: =IF(K25<>"",K25*3,"") -> 2.3633535 | M25: 0 | N25: 0 | O25: 0 | P25: 0 | Q25: 37.35 | R25: 0.01 | S25: =I25/100*M25 -> 0 | T25: =I25/100*N25 -> 0 | U25: =I25/100*O25 -> 0 | V25: =I25/100*P25 -> 0 | W25: =I25/100*Q25 -> 0.85072499 | X25: =I25/100*R25 -> 0.00022777108
A26: 11 | B26: Mista - 50% volumoso fixo | C26: 218 | D26: Mineral | E26: Fosfato Monoamônio Defluorizado | F26: Concentrado | G26: CALCULADA | H26: 0.0061702326 | I26: 0.1 | J26: 98.18 | K26: =IF(J26>0,(I26/J26)/SUMPRODUCT($I$22:$I$28/$J$22:$J$28)*100,"") -> 0.035189074 | L26: =IF(K26<>"",K26*3,"") -> 0.10556722 | M26: 0 | N26: 0 | O26: 0 | P26: 0 | Q26: 1.05 | R26: 23.79 | S26: =I26/100*M26 -> 0 | T26: =I26/100*N26 -> 0 | U26: =I26/100*O26 -> 0 | V26: =I26/100*P26 -> 0 | W26: =I26/100*Q26 -> 0.00105 | X26: =I26/100*R26 -> 0.02379
A27: 11 | B27: Mista - 50% volumoso fixo | C27: 132 | D27: Forragens Verdes | E27: Azevém | F27: Volumoso | G27: CALCULADA | H27: 39.99383 | I27: 50 | J27: 21.43 | K27: =IF(J27>0,(I27/J27)/SUMPRODUCT($I$22:$I$28/$J$22:$J$28)*100,"") -> 80.608103 | L27: =IF(K27<>"",K27*3,"") -> 241.82431 | M27: 13.3 | N27: 64.63 | O27: 57.76 | P27: 2.61 | Q27: 0.49 | R27: 0.27 | S27: =I27/100*M27 -> 6.65 | T27: =I27/100*N27 -> 32.315 | U27: =I27/100*O27 -> 28.88 | V27: =I27/100*P27 -> 1.305 | W27: =I27/100*Q27 -> 0.245 | X27: =I27/100*R27 -> 0.135
A28: 11 | B28: Mista - 50% volumoso fixo | C28: 172 | D28: Energético | E28: Arroz Farelo Integral | F28: Concentrado | G28: CALCULADA | H28: 10 | I28: 18.327272 | J28: 88.98 | K28: =IF(J28>0,(I28/J28)/SUMPRODUCT($I$22:$I$28/$J$22:$J$28)*100,"") -> 7.1160057 | L28: =IF(K28<>"",K28*3,"") -> 21.348017 | M28: 13.73 | N28: 83.51 | O28: 24.43 | P28: 15.84 | Q28: 0.11 | R28: 1.72 | S28: =I28/100*M28 -> 2.5163344 | T28: =I28/100*N28 -> 15.305105 | U28: =I28/100*O28 -> 4.4773525 | V28: =I28/100*P28 -> 2.9030399 | W28: =I28/100*Q28 -> 0.020159999 | X28: =I28/100*R28 -> 0.31522908
